Workbook

Sheet Painel
A1: CÉREBRO DO SITE ALANOL
A2: Use este ficheiro para centralizar produtos, categorias, SEO, CTAs e dados técnicos. Azul = editar; preto = fórmulas; verde = dados ligados/importados.
A4: Indicador | B4: Valor | D4: Como usar | E4: Notas
A5: Total de produtos | B5: =COUNTA(Produtos!A2:A500) | D5: 1) Edita Produtos e Categorias. 2) Usa SEO_Paginas para títulos/descrições. 3) Usa Config para textos globais e CTAs.
A6: Produtos com Solar | B6: =COUNTIF(Produtos!K2:K500,"*Solar*") | D6: No site atual, os produtos vivem no ficheiro js/main.js. Esta folha serve como fonte mestre para copiar/atualizar dados.
A7: Categorias ativas | B7: =COUNTA(Categorias!A2:A50) | D7: A folha Gerador_JS cria linhas de objeto JS simples a partir da tabela Produtos.
A8: Produtos sem URL | B8: =COUNTBLANK(Produtos!I2:I500) | D8: Antes de publicar, confirma URLs, imagens, acentos e especificações técnicas.
A9: Produtos sem texto curto | B9: =COUNTBLANK(Produtos!J2:J500) | D9: Evita promessas absolutas sem confirmação técnica ou certificados.
A10: Última revisão | B10: 2026-04-28 | D10: Mantém a comunicação técnica, direta e orientada à aplicação.

Sheet Config
A1: CONFIGURAÇÕES GLOBAIS
A2: Textos principais, contactos, CTAs e opções de estilo que podem alimentar o site.
A4: Chave | B4: Valor | C4: Tipo | D4: Onde usar | E4: Notas
A5: brand_name | B5: Alanol | C5: texto | D5: Header, SEO, footer
A6: brand_claim | B6: Bombagem de água com engenharia, assistência e resposta técnica. | C6: texto | D6: Hero H1
A7: hero_subtitle | B7: Eletrobombas de furo, poço, superfície e sistemas solares para agricultura, indústria, construção, pressurização e abastecimento. | C7: texto | D7: Hero subtítulo
A8: cta_primary | B8: Ver catálogo técnico | C8: texto | D8: Botões principais
A9: cta_secondary | B9: Pedir seleção de bomba | C9: texto | D9: Botões secundários
A10: phone_fixed | B10: +351 253 501 414 | C10: contacto | D10: Footer/contactos
A11: phone_mobile | B11: +351 914 999 307 | C11: contacto | D11: Footer/contactos
A12: whatsapp | B12: +351 910 178 819 | C12: contacto | D12: Botão flutuante | E12: Confirmar número atual antes de publicar
A13: email | B13: alanol@alanol.pt | C13: contacto | D13: Footer/contactos
A14: primary_color | B14: #0D5AA7 | C14: cor | D14: CSS
A15: dark_color | B15: #071827 | C15: cor | D15: CSS
A16: accent_color | B16: #35A6D8 | C16: cor | D16: CSS

Sheet Categorias
A1: CATEGORIAS
A2: Define famílias de produtos, URLs, textos e cor de cada categoria.
A4: ID Categoria | B4: Nome | C4: Descrição curta | D4: URL / filtro | E4: Cor CSS | F4: Prioridade | G4: Ativa? | H4: CTA
A5: furo | B5: Furo | C5: Bombas submersíveis para captação profunda, abastecimento e rega. | D5: index.html#furo | E5: #0D5AA7 | F5: 1 | G5: Sim | H5: Ver bombas de furo
A6: solar | B6: Solar | C6: Bombagem fotovoltaica off-grid ou híbrida para furos, poços e depósitos. | D6: bombagem-solar.html | E6: #1D7F55 | F6: 2 | G6: Sim | H6: Ver soluções solares
A7: poco | B7: Poço | C7: Bombas de poço, drenagem, águas residuais e serviço contínuo. | D7: index.html#poco | E7: #6B6F76 | F7: 3 | G7: Sim | H7: Ver bombas de poço
A8: superficie | B8: Superfície | C8: Pressurização, grupos de pressão e aplicações industriais. | D8: index.html#superficie | E8: #7030A0 | F8: 4 | G8: Sim | H8: Ver superfície
A9: controlo | B9: Controlo | C9: Quadros, variadores, proteção e pressão constante. | D9: index.html#controlo | E9: #E2A329 | F9: 5 | G9: Sim | H9: Ver controlo
A10: depositos | B10: Depósitos | C10: Depósitos INOX com e sem membrana. | D10: index.html#depositos | E10: #35A6D8 | F10: 6 | G10: Sim | H10: Ver depósitos
A11: acessorios | B11: Acessórios | C11: Peças e acessórios de montagem. | D11: index.html#acessorios | E11: #657487 | F11: 7 | G11: Sim | H11: Ver acessórios

Sheet Produtos
A1: PRODUTOS
A2: Base mestre de produtos. Edita as células azuis. As fórmulas calculam flags úteis para SEO e filtros.
A4: ID | B4: Nome | C4: Categoria | D4: Q máx (m³/h) | E4: H máx (m) | F4: Potência máx (kW) | G4: Imagem | H4: URL | I4: Resumo técnico | J4: Texto curto comercial | K4: Tags | L4: Solar? | M4: Prioridade | N4: Publicado? | O4: Slug calculado | P4: Título SEO sugerido | Q4: Descrição SEO sugerida
A5: 2795 | B5: ALANOL® F4" | C5: furo | D5: 24 | E5: 345 | G5: https://alanol.pt/img/products/f4.png | H5: produtos/eletrobomba-f4.html | I5: Q: 24 m³/h · H: 345 m · Furo 4" | K5: Água Limpa, Rega Agrícola, Rega Residencial, Solar | L5: =IF(ISNUMBER(SEARCH("Solar",K5)),"Sim","Não") | M5: 99 | N5: Sim | O5: =LOWER(SUBSTITUTE(SUBSTITUTE(B5," ","-"),"®","")) | P5: =B5&" | Alanol" | Q5: =LEFT(J5&" "&I5,155)
A6: 4462 | B6: ALANOL® FTI | C6: furo | D6: 270 | E6: 400 | G6: https://alanol.pt/img/products/fti.png | H6: produtos/eletrobomba-fti.html | I6: Qmax: 270 m³/h · Hmax: 400 m · Furo elevado caudal | K6: Água Limpa, Rega Agrícola, Pressurização Edifícios, Campos Desportivos, Solar | L6: =IF(ISNUMBER(SEARCH("Solar",K6)),"Sim","Não") | M6: 99 | N6: Sim | O6: =LOWER(SUBSTITUTE(SUBSTITUTE(B6," ","-"),"®","")) | P6: =B6&" | Alanol" | Q6: =LEFT(J6&" "&I6,155)
A7: 4466 | B7: ALANOL® FTI VS | C7: furo | D7: 120 | E7: 690 | G7: https://alanol.pt/img/products/ftivs.png | H7: produtos/fti-vs.html | I7: Qmax: 120 m³/h · Hmax: 690 m · INOX | K7: Água Limpa, Rega Agrícola, Pressurização Edifícios, Pedreiras, Águas Agressivas, Solar | L7: =IF(ISNUMBER(SEARCH("Solar",K7)),"Sim","Não") | M7: 99 | N7: Sim | O7: =LOWER(SUBSTITUTE(SUBSTITUTE(B7," ","-"),"®","")) | P7: =B7&" | Alanol" | Q7: =LEFT(J7&" "&I7,155)
A8: 9267 | B8: VSC 8"/10" | C8: furo | D8: 342 | E8: 580 | F8: 75 | G8: https://alanol.pt/img/products/vsc.png | H8: produtos/vsc.html | I8: Qmax: 342 m³/h · Hmax: 580 m · INOX | K8: Água Limpa, Rega Agrícola, Pressurização Edifícios, Pedreiras, Águas Agressivas, Solar | L8: =IF(ISNUMBER(SEARCH("Solar",K8)),"Sim","Não") | M8: 99 | N8: Sim | O8: =LOWER(SUBSTITUTE(SUBSTITUTE(B8," ","-"),"®","")) | P8: =B8&" | Alanol" | Q8: =LEFT(J8&" "&I8,155)
A9: 20577 | B9: HES Alta Eficiência 4" | C9: furo | F9: 7.5 | G9: https://alanol.pt/img/products/hes.png | H9: produtos/motores-4-de-alta-eficiencia.html | I9: High Efficiency System · Classe IE3+ | K9: Água Limpa, Rega Agrícola, Rega Residencial, Solar | L9: =IF(ISNUMBER(SEARCH("Solar",K9)),"Sim","Não") | M9: 99 | N9: Sim | O9: =LOWER(SUBSTITUTE(SUBSTITUTE(B9," ","-"),"®","")) | P9: =B9&" | Alanol" | Q9: =LEFT(J9&" "&I9,155)
A10: 4389 | B10: VN — INOX 5" | C10: poco | D10: 14 | E10: 110 | F10: 3 | G10: https://alanol.pt/img/products/vn.png | H10: produtos/vn.html | I10: Q: 14 m³/h · H: 110 m · INOX 5" | K10: Água Limpa, Rega Residencial, Pressurização Unifamiliar, Campos Desportivos, Solar | L10: =IF(ISNUMBER(SEARCH("Solar",K10)),"Sim","Não") | M10: 99 | N10: Sim | O10: =LOWER(SUBSTITUTE(SUBSTITUTE(B10," ","-"),"®","")) | P10: =B10&" | Alanol" | Q10: =LEFT(J10&" "&I10,155)
A11: 4454 | B11: ES — INOX 5" | C11: poco | D11: 7.5 | E11: 90 | F11: 1.1 | G11: https://alanol.pt/img/products/es.png | H11: produtos/es.html | I11: Q: 7,5 m³/h · H: 90 m · INOX 5" | K11: Água Limpa, Rega Residencial, Pressurização Unifamiliar, Campos Desportivos, Solar | L11: =IF(ISNUMBER(SEARCH("Solar",K11)),"Sim","Não") | M11: 99 | N11: Sim | O11: =LOWER(SUBSTITUTE(SUBSTITUTE(B11," ","-"),"®","")) | P11: =B11&" | Alanol" | Q11: =LEFT(J11&" "&I11,155)
A12: 4355 | B12: ALANOL® AM-P / AT-P | C12: poco | D12: 7 | E12: 95 | F12: 2.2 | G12: https://alanol.pt/img/products/amp.png | H12: produtos/amp-atp.html | I12: Pressurização · Alumínio · Série P | K12: Água Limpa, Pressurização Unifamiliar | L12: =IF(ISNUMBER(SEARCH("Solar",K12)),"Sim","Não") | M12: 99 | N12: Sim | O12: =LOWER(SUBSTITUTE(SUBSTITUTE(B12," ","-"),"®","")) | P12: =B12&" | Alanol" | Q12: =LEFT(J12&" "&I12,155)
A13: 4627 | B13: ALANOL® AM-A / AT-A | C13: poco | D13: 51 | E13: 32 | G13: https://alanol.pt/img/products/amat.png | H13: produtos/ama-ata.html | I13: Qmax: 51 m³/h · Hmax: 32 m · Águas abrasivas | K13: Água Lodosa, Rega Agrícola, Águas Agressivas, Pedreiras | L13: =IF(ISNUMBER(SEARCH("Solar",K13)),"Sim","Não") | M13: 99 | N13: Sim | O13: =LOWER(SUBSTITUTE(SUBSTITUTE(B13," ","-"),"®","")) | P13: =B13&" | Alanol" | Q13: =LEFT(J13&" "&I13,155)
A14: 14833 | B14: ALANOL® AM-L / AT-L | C14: poco | D14: 25 | E14: 18 | G14: https://alanol.pt/img/products/aml.png | H14: produtos/am-l-at-l.html | I14: Qmax: 25 m³/h · Hmax: 18 m · Trituradora | K14: Água Suja, Drenagem, Fossa | L14: =IF(ISNUMBER(SEARCH("Solar",K14)),"Sim","Não") | M14: 99 | N14: Sim | O14: =LOWER(SUBSTITUTE(SUBSTITUTE(B14," ","-"),"®","")) | P14: =B14&" | Alanol" | Q14: =LEFT(J14&" "&I14,155)
A15: 4370 | B15: ALANOL® AT-A-B | C15: poco | D15: 51 | E15: 32 | G15: https://alanol.pt/img/products/amat.png | H15: produtos/amab-atab.html | I15: Qmax: 51 m³/h · Hmax: 32 m · Borracha | K15: Água Lodosa, Rega Agrícola, Águas Agressivas | L15: =IF(ISNUMBER(SEARCH("Solar",K15)),"Sim","Não") | M15: 99 | N15: Sim | O15: =LOWER(SUBSTITUTE(SUBSTITUTE(B15," ","-"),"®","")) | P15: =B15&" | Alanol" | Q15: =LEFT(J15&" "&I15,155)
A16: 4364 | B16: ALANOL® AM-1 / AT-1 | C16: poco | D16: 38.5 | E16: 45 | G16: https://alanol.pt/img/products/am1.png | H16: produtos/am1_at1.html | I16: Qmax: 38,5 m³/h · Hmax: 45 m · Alumínio | K16: Água Limpa, Rega Residencial, Rega Agrícola | L16: =IF(ISNUMBER(SEARCH("Solar",K16)),"Sim","Não") | M16: 99 | N16: Sim | O16: =LOWER(SUBSTITUTE(SUBSTITUTE(B16," ","-"),"®","")) | P16: =B16&" | Alanol" | Q16: =LEFT(J16&" "&I16,155)
A17: 4366 | B17: ALANOL® AM-2 / AT-2 | C17: poco | D17: 35 | E17: 58 | G17: https://alanol.pt/img/products/amat.png | H17: produtos/am2-at2.html | I17: Qmax: 35 m³/h · Hmax: 58 m · Duas turbinas | K17: Água Limpa, Rega Residencial, Rega Agrícola | L17: =IF(ISNUMBER(SEARCH("Solar",K17)),"Sim","Não") | M17: 99 | N17: Sim | O17: =LOWER(SUBSTITUTE(SUBSTITUTE(B17," ","-"),"®","")) | P17: =B17&" | Alanol" | Q17: =LEFT(J17&" "&I17,155)
A18: 4380 | B18: ALANOL® AM-A / AT-T | C18: poco | D18: 25 | E18: 18 | G18: https://alanol.pt/img/products/amt.png | H18: produtos/amt-att.html | I18: Qmax: 25 m³/h · Hmax: 18 m · Trituradora | K18: Água Suja, Drenagem, Fossa | L18: =IF(ISNUMBER(SEARCH("Solar",K18)),"Sim","Não") | M18: 99 | N18: Sim | O18: =LOWER(SUBSTITUTE(SUBSTITUTE(B18," ","-"),"®","")) | P18: =B18&" | Alanol" | Q18: =LEFT(J18&" "&I18,155)
A19: 4384 | B19: ALANOL® AM-B / AT-B | C19: poco | D19: 38.5 | E19: 45 | G19: https://alanol.pt/img/products/amb.png | H19: produtos/am_at_b.html | I19: Qmax: 38,5 m³/h · Hmax: 45 m · Bombeiros | K19: Água Suja, Construção, Pedreiras | L19: =IF(ISNUMBER(SEARCH("Solar",K19)),"Sim","Não") | M19: 99 | N19: Sim | O19: =LOWER(SUBSTITUTE(SUBSTITUTE(B19," ","-"),"®","")) | P19: =B19&" | Alanol" | Q19: =LEFT(J19&" "&I19,155)
A20: 11914 | B20: EGN — INOX | C20: poco | D20: 30 | E20: 20 | F20: 1.1 | G20: https://alanol.pt/img/products/egn.png | H20: produtos/egn.html | I20: Q: 30 m³/h · H: 20 m · Drenagem INOX | K20: Água Suja, Drenagem, Solar | L20: =IF(ISNUMBER(SEARCH("Solar",K20)),"Sim","Não") | M20: 99 | N20: Sim | O20: =LOWER(SUBSTITUTE(SUBSTITUTE(B20," ","-"),"®","")) | P20: =B20&" | Alanol" | Q20: =LEFT(J20&" "&I20,155)
A21: 11921 | B21: EGT / EGF — INOX | C21: poco | D21: 36 | E21: 15 | F21: 1.5 | G21: https://alanol.pt/img/products/egtegf.png | H21: produtos/egt-egf.html | I21: Q: 36 m³/h · Sólidos até 50mm | K21: Água Suja, Drenagem, Construção, Pedreiras, Solar | L21: =IF(ISNUMBER(SEARCH("Solar",K21)),"Sim","Não") | M21: 99 | N21: Sim | O21: =LOWER(SUBSTITUTE(SUBSTITUTE(B21," ","-"),"®","")) | P21: =B21&" | Alanol" | Q21: =LEFT(J21&" "&I21,155)
A22: 6635 | B22: ED / EDV — INOX | C22: poco | D22: 26 | E22: 13 | F22: 0.9 | G22: https://alanol.pt/img/products/ededv.png | H22: produtos/ed-edv.html | I22: Qmax: 26 m³/h · Sólidos até 35mm | K22: Água Suja, Drenagem, Fossa, Pedreiras, Construção, Solar | L22: =IF(ISNUMBER(SEARCH("Solar",K22)),"Sim","Não") | M22: 99 | N22: Sim | O22: =LOWER(SUBSTITUTE(SUBSTITUTE(B22," ","-"),"®","")) | P22: =B22&" | Alanol" | Q22: =LEFT(J22&" "&I22,155)
A23: 4441 | B23: EH — Horizontais multiestágio | C23: superficie | D23: 29 | E23: 104 | F23: 15 | G23: https://alanol.pt/img/products/eh.png | H23: produtos/eh.html | I23: Q: 14 m³/h · H: 110 m · INOX | K23: Água Limpa, Pressurização Unifamiliar, Pressurização Edifícios, HVAC / AVAC, Solar | L23: =IF(ISNUMBER(SEARCH("Solar",K23)),"Sim","Não") | M23: 99 | N23: Sim | O23: =LOWER(SUBSTITUTE(SUBSTITUTE(B23," ","-"),"®","")) | P23: =B23&" | Alanol" | Q23: =LEFT(J23&" "&I23,155)
A24: 4457 | B24: EV — Verticais multiestágio | C24: superficie | D24: 120 | E24: 320 | F24: 45 | G24: https://alanol.pt/img/products/ev.png | H24: produtos/ev.html | I24: Q: 120 m³/h · H: 320 m · INOX | K24: Água Limpa, Pressurização Edifícios, Rega Agrícola, HVAC / AVAC, Solar | L24: =IF(ISNUMBER(SEARCH("Solar",K24)),"Sim","Não") | M24: 99 | N24: Sim | O24: =LOWER(SUBSTITUTE(SUBSTITUTE(B24," ","-"),"®","")) | P24: =B24&" | Alanol" | Q24: =LEFT(J24&" "&I24,155)
A25: 7267 | B25: FNC — Monobloco | C25: superficie | G25: https://alanol.pt/img/products/fnc.png | H25: produtos/fnc.html | I25: Monobloco de superfície · Anti-corrosão | K25: Água Limpa, Rega Residencial, Pressurização Unifamiliar, Solar | L25: =IF(ISNUMBER(SEARCH("Solar",K25)),"Sim","Não") | M25: 99 | N25: Sim | O25: =LOWER(SUBSTITUTE(SUBSTITUTE(B25," ","-"),"®","")) | P25: =B25&" | Alanol" | Q25: =LEFT(J25&" "&I25,155)
A26: 4443 | B26: SWT — Piscina | C26: superficie | D26: 34 | E26: 24 | F26: 2.2 | G26: https://alanol.pt/img/products/swt.png | H26: produtos/swt.html | I26: Qmax: 34 m³/h · Hmax: 24 m · Filtro incorporado | K26: Água Limpa | L26: =IF(ISNUMBER(SEARCH("Solar",K26)),"Sim","Não") | M26: 99 | N26: Sim | O26: =LOWER(SUBSTITUTE(SUBSTITUTE(B26," ","-"),"®","")) | P26: =B26&" | Alanol" | Q26: =LEFT(J26&" "&I26,155)
A27: 4483 | B27: Grupo EH24 | C27: superficie | D27: 29 | E27: 104 | F27: 15 | G27: https://alanol.pt/img/products/eh24.png | H27: produtos/eh24.html | I27: Qmax: 7,5 m³/h · Hmax: 104 m | K27: Água Limpa, Pressurização Unifamiliar, HVAC / AVAC, Solar | L27: =IF(ISNUMBER(SEARCH("Solar",K27)),"Sim","Não") | M27: 99 | N27: Sim | O27: =LOWER(SUBSTITUTE(SUBSTITUTE(B27," ","-"),"®","")) | P27: =B27&" | Alanol" | Q27: =LEFT(J27&" "&I27,155)
A28: 4479 | B28: Grupo EH60 | C28: superficie | D28: 29 | E28: 104 | F28: 15 | G28: https://alanol.pt/img/products/eh60.png | H28: produtos/eh-60.html | I28: Qmax: 7 m³/h · Hmax: 104 m | K28: Água Limpa, Pressurização Unifamiliar, HVAC / AVAC, Solar | L28: =IF(ISNUMBER(SEARCH("Solar",K28)),"Sim","Não") | M28: 99 | N28: Sim | O28: =LOWER(SUBSTITUTE(SUBSTITUTE(B28," ","-"),"®","")) | P28: =B28&" | Alanol" | Q28: =LEFT(J28&" "&I28,155)
A29: 4493 | B29: Grupo EH B2 | C29: superficie | D29: 29 | E29: 104 | F29: 15 | G29: https://alanol.pt/img/products/ehb2.png | H29: produtos/eh-b2.html | I29: Qmax: 7 m³/h · Arranque automático | K29: Água Limpa, Pressurização Unifamiliar, HVAC / AVAC, Solar | L29: =IF(ISNUMBER(SEARCH("Solar",K29)),"Sim","Não") | M29: 99 | N29: Sim | O29: =LOWER(SUBSTITUTE(SUBSTITUTE(B29," ","-"),"®","")) | P29: =B29&" | Alanol" | Q29: =LEFT(J29&" "&I29,155)
A30: 4469 | B30: Central EV | C30: superficie | D30: 120 | E30: 320 | F30: 45 | G30: https://alanol.pt/img/products/cev.png | H30: produtos/centrais-ev.html | I30: Qmax: 240 m³/h · Hmax: 320 m | K30: Água Limpa, Pressurização Edifícios, Rega Agrícola, HVAC / AVAC, Solar | L30: =IF(ISNUMBER(SEARCH("Solar",K30)),"Sim","Não") | M30: 99 | N30: Sim | O30: =LOWER(SUBSTITUTE(SUBSTITUTE(B30," ","-"),"®","")) | P30: =B30&" | Alanol" | Q30: =LEFT(J30&" "&I30,155)
A31: 4499 | B31: Central EH230 | C31: superficie | D31: 29 | E31: 104 | F31: 15 | G31: https://alanol.pt/img/products/eh230.png | H31: produtos/central-inteligente-eh-se230.html | I31: Variadores integrados · Pressão constante | K31: Água Limpa, Pressurização Edifícios, Pressurização Unifamiliar, HVAC / AVAC, Solar | L31: =IF(ISNUMBER(SEARCH("Solar",K31)),"Sim","Não") | M31: 99 | N31: Sim | O31: =LOWER(SUBSTITUTE(SUBSTITUTE(B31," ","-"),"®","")) | P31: =B31&" | Alanol" | Q31: =LEFT(J31&" "&I31,155)
A32: 4508 | B32: Central EH BT | C32: superficie | D32: 29 | E32: 104 | F32: 15 | G32: https://alanol.pt/img/products/ehbt.png | H32: produtos/centrais-eh-bt.html | I32: Qmax: 15 m³/h · Hmax: 104 m | K32: Água Limpa, Pressurização Unifamiliar, HVAC / AVAC, Solar | L32: =IF(ISNUMBER(SEARCH("Solar",K32)),"Sim","Não") | M32: 99 | N32: Sim | O32: =LOWER(SUBSTITUTE(SUBSTITUTE(B32," ","-"),"®","")) | P32: =B32&" | Alanol" | Q32: =LEFT(J32&" "&I32,155)
A33: 4472 | B33: Central VL | C33: superficie | D33: 24 | E33: 104 | G33: https://alanol.pt/img/products/cvl.png | H33: produtos/centrais-vl.html | I33: Qmax: 24 m³/h · Hmax: 104 m | K33: Água Limpa, Pressurização Unifamiliar, Pressurização Edifícios, HVAC / AVAC, Solar | L33: =IF(ISNUMBER(SEARCH("Solar",K33)),"Sim","Não") | M33: 99 | N33: Sim | O33: =LOWER(SUBSTITUTE(SUBSTITUTE(B33," ","-"),"®","")) | P33: =B33&" | Alanol" | Q33: =LEFT(J33&" "&I33,155)
A34: 10324 | B34: Kits Bombagem Solar | C34: solar | D34: 24 | E34: 345 | G34: https://alanol.pt/img/products/solar.webp | H34: produtos/kits-de-bombagem-solar.html | I34: Q: 24 m³/h · H: 345 m · Kit completo | K34: Água Limpa, Rega Agrícola, Rega Residencial, Campos Desportivos | L34: =IF(ISNUMBER(SEARCH("Solar",K34)),"Sim","Não") | M34: 99 | N34: Sim | O34: =LOWER(SUBSTITUTE(SUBSTITUTE(B34," ","-"),"®","")) | P34: =B34&" | Alanol" | Q34: =LEFT(J34&" "&I34,155)
A35: 11503 | B35: Drive-Tech® Mini Solar MP | C35: solar | F35: 1.5 | G35: https://alanol.pt/img/products/drive-tech-mini.png | H35: produtos/controlador-solar-drive-tech.html | I35: 3×230V · Max 1,5 kW · Bluetooth | K35: Água Limpa, Rega Agrícola, Rega Residencial, Campos Desportivos | L35: =IF(ISNUMBER(SEARCH("Solar",K35)),"Sim","Não") | M35: 99 | N35: Sim | O35: =LOWER(SUBSTITUTE(SUBSTITUTE(B35," ","-"),"®","")) | P35: =B35&" | Alanol" | Q35: =LEFT(J35&" "&I35,155)
A36: 11504 | B36: Drive-Tech® Solar | C36: solar | F36: 22 | G36: https://alanol.pt/img/products/dtech.png | H36: produtos/drive-tech-compact-solar.html | I36: até 22 kW · MPPT · 3×380-460 V · Bluetooth | K36: Água Limpa, Rega Agrícola, Pressurização Edifícios, Campos Desportivos | L36: =IF(ISNUMBER(SEARCH("Solar",K36)),"Sim","Não") | M36: 99 | N36: Sim | O36: =LOWER(SUBSTITUTE(SUBSTITUTE(B36," ","-"),"®","")) | P36: =B36&" | Alanol" | Q36: =LEFT(J36&" "&I36,155)
A37: 4521 | B37: Depósito s/ Membrana INOX | C37: depositos | G37: https://alanol.pt/img/products/dep1.png | H37: produtos/depositos-sem-membrana-em-inox.html | I37: 100 a 1300 litros · INOX | K37: Água Limpa, Pressurização Unifamiliar, Pressurização Edifícios, HVAC / AVAC | L37: =IF(ISNUMBER(SEARCH("Solar",K37)),"Sim","Não") | M37: 99 | N37: Sim | O37: =LOWER(SUBSTITUTE(SUBSTITUTE(B37," ","-"),"®","")) | P37: =B37&" | Alanol" | Q37: =LEFT(J37&" "&I37,155)
A38: 6783 | B38: Depósito c/ Membrana INOX | C38: depositos | G38: https://alanol.pt/img/products/dep2.png | H38: produtos/depositos-com-membrana-inox.html | I38: 24 a 500 litros · INOX | K38: Água Limpa, Pressurização Unifamiliar, HVAC / AVAC | L38: =IF(ISNUMBER(SEARCH("Solar",K38)),"Sim","Não") | M38: 99 | N38: Sim | O38: =LOWER(SUBSTITUTE(SUBSTITUTE(B38," ","-"),"®","")) | P38: =B38&" | Alanol" | Q38: =LEFT(J38&" "&I38,155)
A39: 6926 | B39: Quadro Digital TPM6 | C39: controlo | G39: https://alanol.pt/img/products/tpm6.png | H39: produtos/tpm6.html | I39: Digital · Com ou sem sondas | K39: Água Limpa, Água Suja, Pressurização Unifamiliar | L39: =IF(ISNUMBER(SEARCH("Solar",K39)),"Sim","Não") | M39: 99 | N39: Sim | O39: =LOWER(SUBSTITUTE(SUBSTITUTE(B39," ","-"),"®","")) | P39: =B39&" | Alanol" | Q39: =LEFT(J39&" "&I39,155)
A40: 6925 | B40: Quadro Digital PROBOMBA | C40: controlo | G40: https://alanol.pt/img/products/probomba.png | H40: produtos/probomba.html | I40: Digital · Dispensa sondas | K40: Água Limpa, Pressurização Unifamiliar, Pressurização Edifícios | L40: =IF(ISNUMBER(SEARCH("Solar",K40)),"Sim","Não") | M40: 99 | N40: Sim | O40: =LOWER(SUBSTITUTE(SUBSTITUTE(B40," ","-"),"®","")) | P40: =B40&" | Alanol" | Q40: =LEFT(J40&" "&I40,155)
A41: 6927 | B41: PROBOMBA Águas Residuais | C41: controlo | G41: https://alanol.pt/img/products/probar.png | H41: produtos/probomba-ar.html | I41: Proteção e comando · Águas residuais | K41: Água Suja, Drenagem, Fossa | L41: =IF(ISNUMBER(SEARCH("Solar",K41)),"Sim","Não") | M41: 99 | N41: Sim | O41: =LOWER(SUBSTITUTE(SUBSTITUTE(B41," ","-"),"®","")) | P41: =B41&" | Alanol" | Q41: =LEFT(J41&" "&I41,155)
...

Sheet Tags
A1: TAGS E APLICAÇÕES
A2: Vocabulário controlado para filtros, SEO e consistência comercial.
A4: Tag | B4: Grupo | C4: Descrição | D4: Usar em produtos? | E4: Prioridade
A5: Acessórios de Montagem | B5: Sistema | D5: Sim | E5: 1
A6: Campos Desportivos | B6: Aplicação | D6: Sim | E6: 2
A7: Construção | B7: Aplicação | D7: Sim | E7: 3
A8: Drenagem | B8: Aplicação | D8: Sim | E8: 4
A9: Fossa | B9: Aplicação | D9: Sim | E9: 5
A10: HVAC / AVAC | B10: Aplicação | D10: Sim | E10: 6
A11: Motores Submersíveis | B11: Sistema | D11: Sim | E11: 7
A12: Pedreiras | B12: Aplicação | D12: Sim | E12: 8
A13: Pressurização Edifícios | B13: Aplicação | D13: Sim | E13: 9
A14: Pressurização Unifamiliar | B14: Aplicação | D14: Sim | E14: 10
A15: Rega Agrícola | B15: Aplicação | D15: Sim | E15: 11
A16: Rega Residencial | B16: Aplicação | D16: Sim | E16: 12
... A21: Águas Agressivas | B21: Tipo de água | D21: Sim | E21: 17

Sheet SEO_Paginas
A1: SEO DAS PÁGINAS
A2: Planeia titles, meta descriptions e keywords principais. Usa contadores para evitar títulos/descrições demasiado longos.
A4: Página | B4: URL | C4: Keyword principal | D4: Title SEO | E4: Caracteres Title | F4: Meta Description | G4: Caracteres Description | H4: H1 | I4: Estado | J4: Notas
A5: Homepage | B5: index.html | C5: eletrobombas submersíveis | D5: Eletrobombas Submersíveis e Bombagem Solar | Alanol | E5: =LEN(D5) | F5: Bombas de furo, poço, superfície e sistemas solares para agricultura, indústria e construção. Apoio técnico Alanol desde 1959. | G5: =LEN(F5) | H5: Bombagem de água com engenharia, assistência e resposta técnica. | I5: Revisto
A6: Bombagem Solar | B6: bombagem-solar.html | C6: bombagem solar | D6: Bombagem Solar para Furos, Poços e Rega | Alanol | E6: =LEN(D6) | F6: Sistemas de bombagem solar com Drive-Tech para furos, poços, depósitos e rega agrícola. Soluções off-grid e híbridas. | G6: =LEN(F6) | H6: Bombagem Solar | I6: A rever
A7: Contactos | B7: contactos.html | C7: contactos Alanol | D7: Contactos Alanol | Apoio Técnico em Bombagem | E7: =LEN(D7) | F7: Fale com a Alanol para seleção de bombas, assistência técnica, orçamento e apoio em sistemas de bombagem. | G7: =LEN(F7) | H7: Contactos | I7: A rever

Sheet CTA_Textos
A1: TEXTOS E CTAS
A2: Banco de chamadas à ação, headlines e microcopy para testes no site.
A4: Tipo | B4: Texto | C4: Página/Secção | D4: Intenção | E4: Prioridade | F4: Ativo?
A5: Hero H1 | B5: Bombagem de água com engenharia, assistência e resposta técnica. | C5: Homepage Hero | D5: Autoridade | E5: 1 | F5: Sim
A6: Botão | B6: Pedir seleção de bomba | C6: Hero / CTA final | D6: Lead técnico | E6: 1 | F6: Sim
A7: Botão | B7: Ver catálogo técnico | C7: Hero | D7: Catálogo | E7: 2 | F7: Sim
A8: Headline | B8: Dimensionamos soluções para a água chegar onde é precisa. | C8: Intro | D8: Posicionamento | E8: 1 | F8: Sim
A9: Microcopy | B9: A resposta certa começa com os dados certos. | C9: CTA final | D9: Confiança | E9: 1 | F9: Sim
A10: WhatsApp | B10: WhatsApp técnico | C10: CTA final | D10: Contacto rápido | E10: 2 | F10: Sim

Sheet Calculadora_Furo
A1: CALCULADORA SIMPLES DE FURO
A2: Estimativa inicial. Não substitui curva hidráulica nem validação técnica.
A4: Entrada | B4: Valor | C4: Unidade / nota
A5: Caudal pretendido (m³/h) | B5: 5 | C5: editar
A6: Profundidade / nível dinâmico (m) | B6: 90 | C6: editar
A7: Desnível adicional (m) | B7: 10 | C7: editar
A8: Comprimento tubagem (m) | B8: 120 | C8: editar
A9: Perdas estimadas por 100 m (%) | B9: 8 | C9: editar
A10: Pressão desejada à saída (bar) | B10: 2 | C10: editar
A13: Resultado | B13: Valor | C13: Fórmula
A14: Pressão desejada convertida em metros | B14: =B10*10.2 | C14: bar × 10,2
A15: Perdas de carga estimadas | B15: =B8*(B9/100)*(B5/5) | C15: comprimento × % perdas × ajuste caudal
A16: Altura manométrica total estimada | B16: =B6+B7+B14+B15 | C16: nível dinâmico + desnível + pressão + perdas
A17: Potência hidráulica aproximada (kW) | B17: =B5*B16/367 | C17: Q × H / 367
A18: Potência motor sugerida c/ rendimento 55% | B18: =B17/0.55 | C18: estimativa inicial
A21: Aviso | B21: Esta folha é apenas uma pré-seleção. Confirmar sempre com curva da bomba, perdas reais, cabos, proteções e condições do furo.

Sheet Gerador_JS
A1: GERADOR JS
A2: Ajuda a copiar produtos da folha Produtos para objetos JS. Fórmula simples, sem arrays dinâmicos.
A4: Linha JS aproximada
A5: =IF(Produtos!A5="","","{id:"&Produtos!A5&", cat:""&Produtos!C5&"", tags:[""&SUBSTITUTE(Produtos!K5,", ","","")&""], q:"&IF(Produtos!D5="","null",Produtos!D5)&", h:"&IF(Produtos!E5="","null",Produtos!E5)&", kw:"&IF(Produtos!F5="","null",Produtos!F5)&", name:""&Produtos!B5&"", img:""&Produtos!G5&"", spec:""&Produtos!I5&"", url:""&Produtos!H5&""},")
A6: =IF(Produtos!A6="","","{id:"&Produtos!A6&", cat:""&Produtos!C6&"", tags:[""&SUBSTITUTE(Produtos!K6,", ","","")&""], q:"&IF(Produtos!D6="","null",Produtos!D6)&", h:"&IF(Produtos!E6="","null",Produtos!E6)&", kw:"&IF(Produtos!F6="","null",Produtos!F6)&", name:""&Produtos!B6&"", img:""&Produtos!G6&"", spec:""&Produtos!I6&"", url:""&Produtos!H6&""},")
A7: =IF(Produtos!A7="","","{id:"&Produtos!A7&", cat:""&Produtos!C7&"", tags:[""&SUBSTITUTE(Produtos!K7,", ","","")&""], q:"&IF(Produtos!D7="","null",Produtos!D7)&", h:"&IF(Produtos!E7="","null",Produtos!E7)&", kw:"&IF(Produtos!F7="","null",Produtos!F7)&", name:""&Produtos!B7&"", img:""&Produtos!G7&"", spec:""&Produtos!I7&"", url:""&Produtos!H7&""},")
A8: =IF(Produtos!A8="","","{id:"&Produtos!A8&", cat:""&Produtos!C8&"", tags:[""&SUBSTITUTE(Produtos!K8,", ","","")&""], q:"&IF(Produtos!D8="","null",Produtos!D8)&", h:"&IF(Produtos!E8="","null",Produtos!E8)&", kw:"&IF(Produtos!F8="","null",Produtos!F8)&", name:""&Produtos!B8&"", img:""&Produtos!G8&"", spec:""&Produtos!I8&"", url:""&Produtos!H8&""},")
A9: =IF(Produtos!A9="","","{id:"&Produtos!A9&", cat:""&Produtos!C9&"", tags:[""&SUBSTITUTE(Produtos!K9,", ","","")&""], q:"&IF(Produtos!D9="","null",Produtos!D9)&", h:"&IF(Produtos!E9="","null",Produtos!E9)&", kw:"&IF(Produtos!F9="","null",Produtos!F9)&", name:""&Produtos!B9&"", img:""&Produtos!G9&"", spec:""&Produtos!I9&"", url:""&Produtos!H9&""},")
A10: =IF(Produtos!A10="","","{id:"&Produtos!A10&", cat:""&Produtos!C10&"", tags:[""&SUBSTITUTE(Produtos!K10,", ","","")&""], q:"&IF(Produtos!D10="","null",Produtos!D10)&", h:"&IF(Produtos!E10="","null",Produtos!E10)&", kw:"&IF(Produtos!F10="","null",Produtos!F10)&", name:""&Produtos!B10&"", img:""&Produtos!G10&"", spec:""&Produtos!I10&"", url:""&Produtos!H10&""},")
A11: =IF(Produtos!A11="","","{id:"&Produtos!A11&", cat:""&Produtos!C11&"", tags:[""&SUBSTITUTE(Produtos!K11,", ","","")&""], q:"&IF(Produtos!D11="","null",Produtos!D11)&", h:"&IF(Produtos!E11="","null",Produtos!E11)&", kw:"&IF(Produtos!F11="","null",Produtos!F11)&", name:""&Produtos!B11&"", img:""&Produtos!G11&"", spec:""&Produtos!I11&"", url:""&Produtos!H11&""},")
A12: =IF(Produtos!A12="","","{id:"&Produtos!A12&", cat:""&Produtos!C12&"", tags:[""&SUBSTITUTE(Produtos!K12,", ","","")&""], q:"&IF(Produtos!D12="","null",Produtos!D12)&", h:"&IF(Produtos!E12="","null",Produtos!E12)&", kw:"&IF(Produtos!F12="","null",Produtos!F12)&", name:""&Produtos!B12&"", img:""&Produtos!G12&"", spec:""&Produtos!I12&"", url:""&Produtos!H12&""},")
A13: =IF(Produtos!A13="","","{id:"&Produtos!A13&", cat:""&Produtos!C13&"", tags:[""&SUBSTITUTE(Produtos!K13,", ","","")&""], q:"&IF(Produtos!D13="","null",Produtos!D13)&", h:"&IF(Produtos!E13="","null",Produtos!E13)&", kw:"&IF(Produtos!F13="","null",Produtos!F13)&", name:""&Produtos!B13&"", img:""&Produtos!G13&"", spec:""&Produtos!I13&"", url:""&Produtos!H13&""},")
A14: =IF(Produtos!A14="","","{id:"&Produtos!A14&", cat:""&Produtos!C14&"", tags:[""&SUBSTITUTE(Produtos!K14,", ","","")&""], q:"&IF(Produtos!D14="","null",Produtos!D14)&", h:"&IF(Produtos!E14="","null",Produtos!E14)&", kw:"&IF(Produtos!F14="","null",Produtos!F14)&", name:""&Produtos!B14&"", img:""&Produtos!G14&"", spec:""&Produtos!I14&"", url:""&Produtos!H14&""},")
A15: =IF(Produtos!A15="","","{id:"&Produtos!A15&", cat:""&Produtos!C15&"", tags:[""&SUBSTITUTE(Produtos!K15,", ","","")&""], q:"&IF(Produtos!D15="","null",Produtos!D15)&", h:"&IF(Produtos!E15="","null",Produtos!E15)&", kw:"&IF(Produtos!F15="","null",Produtos!F15)&", name:""&Produtos!B15&"", img:""&Produtos!G15&"", spec:""&Produtos!I15&"", url:""&Produtos!H15&""},")
A16: =IF(Produtos!A16="","","{id:"&Produtos!A16&", cat:""&Produtos!C16&"", tags:[""&SUBSTITUTE(Produtos!K16,", ","","")&""], q:"&IF(Produtos!D16="","null",Produtos!D16)&", h:"&IF(Produtos!E16="","null",Produtos!E16)&", kw:"&IF(Produtos!F16="","null",Produtos!F16)&", name:""&Produtos!B16&"", img:""&Produtos!G16&"", spec:""&Produtos!I16&"", url:""&Produtos!H16&""},")
A17: =IF(Produtos!A17="","","{id:"&Produtos!A17&", cat:""&Produtos!C17&"", tags:[""&SUBSTITUTE(Produtos!K17,", ","","")&""], q:"&IF(Produtos!D17="","null",Produtos!D17)&", h:"&IF(Produtos!E17="","null",Produtos!E17)&", kw:"&IF(Produtos!F17="","null",Produtos!F17)&", name:""&Produtos!B17&"", img:""&Produtos!G17&"", spec:""&Produtos!I17&"", url:""&Produtos!H17&""},")
A18: =IF(Produtos!A18="","","{id:"&Produtos!A18&", cat:""&Produtos!C18&"", tags:[""&SUBSTITUTE(Produtos!K18,", ","","")&""], q:"&IF(Produtos!D18="","null",Produtos!D18)&", h:"&IF(Produtos!E18="","null",Produtos!E18)&", kw:"&IF(Produtos!F18="","null",Produtos!F18)&", name:""&Produtos!B18&"", img:""&Produtos!G18&"", spec:""&Produtos!I18&"", url:""&Produtos!H18&""},")
A19: =IF(Produtos!A19="","","{id:"&Produtos!A19&", cat:""&Produtos!C19&"", tags:[""&SUBSTITUTE(Produtos!K19,", ","","")&""], q:"&IF(Produtos!D19="","null",Produtos!D19)&", h:"&IF(Produtos!E19="","null",Produtos!E19)&", kw:"&IF(Produtos!F19="","null",Produtos!F19)&", name:""&Produtos!B19&"", img:""&Produtos!G19&"", spec:""&Produtos!I19&"", url:""&Produtos!H19&""},")
A20: =IF(Produtos!A20="","","{id:"&Produtos!A20&", cat:""&Produtos!C20&"", tags:[""&SUBSTITUTE(Produtos!K20,", ","","")&""], q:"&IF(Produtos!D20="","null",Produtos!D20)&", h:"&IF(Produtos!E20="","null",Produtos!E20)&", kw:"&IF(Produtos!F20="","null",Produtos!F20)&", name:""&Produtos!B20&"", img:""&Produtos!G20&"", spec:""&Produtos!I20&"", url:""&Produtos!H20&""},")
A21: =IF(Produtos!A21="","","{id:"&Produtos!A21&", cat:""&Produtos!C21&"", tags:[""&SUBSTITUTE(Produtos!K21,", ","","")&""], q:"&IF(Produtos!D21="","null",Produtos!D21)&", h:"&IF(Produtos!E21="","null",Produtos!E21)&", kw:"&IF(Produtos!F21="","null",Produtos!F21)&", name:""&Produtos!B21&"", img:""&Produtos!G21&"", spec:""&Produtos!I21&"", url:""&Produtos!H21&""},")
A22: =IF(Produtos!A22="","","{id:"&Produtos!A22&", cat:""&Produtos!C22&"", tags:[""&SUBSTITUTE(Produtos!K22,", ","","")&""], q:"&IF(Produtos!D22="","null",Produtos!D22)&", h:"&IF(Produtos!E22="","null",Produtos!E22)&", kw:"&IF(Produtos!F22="","null",Produtos!F22)&", name:""&Produtos!B22&"", img:""&Produtos!G22&"", spec:""&Produtos!I22&"", url:""&Produtos!H22&""},")
A23: =IF(Produtos!A23="","","{id:"&Produtos!A23&", cat:""&Produtos!C23&"", tags:[""&SUBSTITUTE(Produtos!K23,", ","","")&""], q:"&IF(Produtos!D23="","null",Produtos!D23)&", h:"&IF(Produtos!E23="","null",Produtos!E23)&", kw:"&IF(Produtos!F23="","null",Produtos!F23)&", name:""&Produtos!B23&"", img:""&Produtos!G23&"", spec:""&Produtos!I23&"", url:""&Produtos!H23&""},")
A24: =IF(Produtos!A24="","","{id:"&Produtos!A24&", cat:""&Produtos!C24&"", tags:[""&SUBSTITUTE(Produtos!K24,", ","","")&""], q:"&IF(Produtos!D24="","null",Produtos!D24)&", h:"&IF(Produtos!E24="","null",Produtos!E24)&", kw:"&IF(Produtos!F24="","null",Produtos!F24)&", name:""&Produtos!B24&"", img:""&Produtos!G24&"", spec:""&Produtos!I24&"", url:""&Produtos!H24&""},")
A25: =IF(Produtos!A25="","","{id:"&Produtos!A25&", cat:""&Produtos!C25&"", tags:[""&SUBSTITUTE(Produtos!K25,", ","","")&""], q:"&IF(Produtos!D25="","null",Produtos!D25)&", h:"&IF(Produtos!E25="","null",Produtos!E25)&", kw:"&IF(Produtos!F25="","null",Produtos!F25)&", name:""&Produtos!B25&"", img:""&Produtos!G25&"", spec:""&Produtos!I25&"", url:""&Produtos!H25&""},")
A26: =IF(Produtos!A26="","","{id:"&Produtos!A26&", cat:""&Produtos!C26&"", tags:[""&SUBSTITUTE(Produtos!K26,", ","","")&""], q:"&IF(Produtos!D26="","null",Produtos!D26)&", h:"&IF(Produtos!E26="","null",Produtos!E26)&", kw:"&IF(Produtos!F26="","null",Produtos!F26)&", name:""&Produtos!B26&"", img:""&Produtos!G26&"", spec:""&Produtos!I26&"", url:""&Produtos!H26&""},")
A27: =IF(Produtos!A27="","","{id:"&Produtos!A27&", cat:""&Produtos!C27&"", tags:[""&SUBSTITUTE(Produtos!K27,", ","","")&""], q:"&IF(Produtos!D27="","null",Produtos!D27)&", h:"&IF(Produtos!E27="","null",Produtos!E27)&", kw:"&IF(Produtos!F27="","null",Produtos!F27)&", name:""&Produtos!B27&"", img:""&Produtos!G27&"", spec:""&Produtos!I27&"", url:""&Produtos!H27&""},")
A28: =IF(Produtos!A28="","","{id:"&Produtos!A28&", cat:""&Produtos!C28&"", tags:[""&SUBSTITUTE(Produtos!K28,", ","","")&""], q:"&IF(Produtos!D28="","null",Produtos!D28)&", h:"&IF(Produtos!E28="","null",Produtos!E28)&", kw:"&IF(Produtos!F28="","null",Produtos!F28)&", name:""&Produtos!B28&"", img:""&Produtos!G28&"", spec:""&Produtos!I28&"", url:""&Produtos!H28&""},")
A29: =IF(Produtos!A29="","","{id:"&Produtos!A29&", cat:""&Produtos!C29&"", tags:[""&SUBSTITUTE(Produtos!K29,", ","","")&""], q:"&IF(Produtos!D29="","null",Produtos!D29)&", h:"&IF(Produtos!E29="","null",Produtos!E29)&", kw:"&IF(Produtos!F29="","null",Produtos!F29)&", name:""&Produtos!B29&"", img:""&Produtos!G29&"", spec:""&Produtos!I29&"", url:""&Produtos!H29&""},")
A30: =IF(Produtos!A30="","","{id:"&Produtos!A30&", cat:""&Produtos!C30&"", tags:[""&SUBSTITUTE(Produtos!K30,", ","","")&""], q:"&IF(Produtos!D30="","null",Produtos!D30)&", h:"&IF(Produtos!E30="","null",Produtos!E30)&", kw:"&IF(Produtos!F30="","null",Produtos!F30)&", name:""&Produtos!B30&"", img:""&Produtos!G30&"", spec:""&Produtos!I30&"", url:""&Produtos!H30&""},")
A31: =IF(Produtos!A31="","","{id:"&Produtos!A31&", cat:""&Produtos!C31&"", tags:[""&SUBSTITUTE(Produtos!K31,", ","","")&""], q:"&IF(Produtos!D31="","null",Produtos!D31)&", h:"&IF(Produtos!E31="","null",Produtos!E31)&", kw:"&IF(Produtos!F31="","null",Produtos!F31)&", name:""&Produtos!B31&"", img:""&Produtos!G31&"", spec:""&Produtos!I31&"", url:""&Produtos!H31&""},")
A32: =IF(Produtos!A32="","","{id:"&Produtos!A32&", cat:""&Produtos!C32&"", tags:[""&SUBSTITUTE(Produtos!K32,", ","","")&""], q:"&IF(Produtos!D32="","null",Produtos!D32)&", h:"&IF(Produtos!E32="","null",Produtos!E32)&", kw:"&IF(Produtos!F32="","null",Produtos!F32)&", name:""&Produtos!B32&"", img:""&Produtos!G32&"", spec:""&Produtos!I32&"", url:""&Produtos!H32&""},")
A33: =IF(Produtos!A33="","","{id:"&Produtos!A33&", cat:""&Produtos!C33&"", tags:[""&SUBSTITUTE(Produtos!K33,", ","","")&""], q:"&IF(Produtos!D33="","null",Produtos!D33)&", h:"&IF(Produtos!E33="","null",Produtos!E33)&", kw:"&IF(Produtos!F33="","null",Produtos!F33)&", name:""&Produtos!B33&"", img:""&Produtos!G33&"", spec:""&Produtos!I33&"", url:""&Produtos!H33&""},")
A34: =IF(Produtos!A34="","","{id:"&Produtos!A34&", cat:""&Produtos!C34&"", tags:[""&SUBSTITUTE(Produtos!K34,", ","","")&""], q:"&IF(Produtos!D34="","null",Produtos!D34)&", h:"&IF(Produtos!E34="","null",Produtos!E34)&", kw:"&IF(Produtos!F34="","null",Produtos!F34)&", name:""&Produtos!B34&"", img:""&Produtos!G34&"", spec:""&Produtos!I34&"", url:""&Produtos!H34&""},")
A35: =IF(Produtos!A35="","","{id:"&Produtos!A35&", cat:""&Produtos!C35&"", tags:[""&SUBSTITUTE(Produtos!K35,", ","","")&""], q:"&IF(Produtos!D35="","null",Produtos!D35)&", h:"&IF(Produtos!E35="","null",Produtos!E35)&", kw:"&IF(Produtos!F35="","null",Produtos!F35)&", name:""&Produtos!B35&"", img:""&Produtos!G35&"", spec:""&Produtos!I35&"", url:""&Produtos!H35&""},")
A36: =IF(Produtos!A36="","","{id:"&Produtos!A36&", cat:""&Produtos!C36&"", tags:[""&SUBSTITUTE(Produtos!K36,", ","","")&""], q:"&IF(Produtos!D36="","null",Produtos!D36)&", h:"&IF(Produtos!E36="","null",Produtos!E36)&", kw:"&IF(Produtos!F36="","null",Produtos!F36)&", name:""&Produtos!B36&"", img:""&Produtos!G36&"", spec:""&Produtos!I36&"", url:""&Produtos!H36&""},")
A37: =IF(Produtos!A37="","","{id:"&Produtos!A37&", cat:""&Produtos!C37&"", tags:[""&SUBSTITUTE(Produtos!K37,", ","","")&""], q:"&IF(Produtos!D37="","null",Produtos!D37)&", h:"&IF(Produtos!E37="","null",Produtos!E37)&", kw:"&IF(Produtos!F37="","null",Produtos!F37)&", name:""&Produtos!B37&"", img:""&Produtos!G37&"", spec:""&Produtos!I37&"", url:""&Produtos!H37&""},")
A38: =IF(Produtos!A38="","","{id:"&Produtos!A38&", cat:""&Produtos!C38&"", tags:[""&SUBSTITUTE(Produtos!K38,", ","","")&""], q:"&IF(Produtos!D38="","null",Produtos!D38)&", h:"&IF(Produtos!E38="","null",Produtos!E38)&", kw:"&IF(Produtos!F38="","null",Produtos!F38)&", name:""&Produtos!B38&"", img:""&Produtos!G38&"", spec:""&Produtos!I38&"", url:""&Produtos!H38&""},")
A39: =IF(Produtos!A39="","","{id:"&Produtos!A39&", cat:""&Produtos!C39&"", tags:[""&SUBSTITUTE(Produtos!K39,", ","","")&""], q:"&IF(Produtos!D39="","null",Produtos!D39)&", h:"&IF(Produtos!E39="","null",Produtos!E39)&", kw:"&IF(Produtos!F39="","null",Produtos!F39)&", name:""&Produtos!B39&"", img:""&Produtos!G39&"", spec:""&Produtos!I39&"", url:""&Produtos!H39&""},")
A40: =IF(Produtos!A40="","","{id:"&Produtos!A40&", cat:""&Produtos!C40&"", tags:[""&SUBSTITUTE(Produtos!K40,", ","","")&""], q:"&IF(Produtos!D40="","null",Produtos!D40)&", h:"&IF(Produtos!E40="","null",Produtos!E40)&", kw:"&IF(Produtos!F40="","null",Produtos!F40)&", name:""&Produtos!B40&"", img:""&Produtos!G40&"", spec:""&Produtos!I40&"", url:""&Produtos!H40&""},")
A41: =IF(Produtos!A41="","","{id:"&Produtos!A41&", cat:""&Produtos!C41&"", tags:[""&SUBSTITUTE(Produtos!K41,", ","","")&""], q:"&IF(Produtos!D41="","null",Produtos!D41)&", h:"&IF(Produtos!E41="","null",Produtos!E41)&", kw:"&IF(Produtos!F41="","null",Produtos!F41)&", name:""&Produtos!B41&"", img:""&Produtos!G41&"", spec:""&Produtos!I41&"", url:""&Produtos!H41&""},")
...
